Traceback (most recent call last):
  File "C:\Users\chenoi\anaconda3\lib\site-packages\jupyter_cache\executors\utils.py", line 58, in single_nb_execution
    executenb(
  File "C:\Users\chenoi\anaconda3\lib\site-packages\nbclient\client.py", line 1204, in execute
    return NotebookClient(nb=nb, resources=resources, km=km, **kwargs).execute()
  File "C:\Users\chenoi\anaconda3\lib\site-packages\nbclient\util.py", line 84, in wrapped
    return just_run(coro(*args, **kwargs))
  File "C:\Users\chenoi\anaconda3\lib\site-packages\nbclient\util.py", line 62, in just_run
    return loop.run_until_complete(coro)
  File "C:\Users\chenoi\anaconda3\lib\asyncio\base_events.py", line 647, in run_until_complete
    return future.result()
  File "C:\Users\chenoi\anaconda3\lib\site-packages\nbclient\client.py", line 663, in async_execute
    await self.async_execute_cell(
  File "C:\Users\chenoi\anaconda3\lib\site-packages\nbclient\client.py", line 965, in async_execute_cell
    await self._check_raise_for_error(cell, cell_index, exec_reply)
  File "C:\Users\chenoi\anaconda3\lib\site-packages\nbclient\client.py", line 862, in _check_raise_for_error
    raise CellExecutionError.from_cell_and_msg(cell, exec_reply_content)
nbclient.exceptions.CellExecutionError: An error occurred while executing the following cell:
------------------
%matplotlib inline
import matplotlib.pyplot as plt
plt.rcParams["figure.figsize"] = (11, 5)  #set default figure size
import numpy as np
import quantecon as qe
from interpolation import interp
from numpy.random import randn
from numba import njit, prange, float64
from numba.experimental import jitclass
------------------

[1;31m---------------------------------------------------------------------------[0m
[1;31mSystemError[0m                               Traceback (most recent call last)
[1;32m~\anaconda3\lib\site-packages\quantecon\__init__.py[0m in [0;36m<module>[1;34m[0m
[0;32m      8[0m [1;32mtry[0m[1;33m:[0m[1;33m[0m[1;33m[0m[0m
[1;32m----> 9[1;33m     [1;32mimport[0m [0mnumba[0m[1;33m[0m[1;33m[0m[0m
[0m[0;32m     10[0m [1;32mexcept[0m[1;33m:[0m[1;33m[0m[1;33m[0m[0m

[1;32m~\anaconda3\lib\site-packages\numba\__init__.py[0m in [0;36m<module>[1;34m[0m
[0;32m     41[0m [1;31m# Re-export vectorize decorators and the thread layer querying function[0m[1;33m[0m[1;33m[0m[0m
[1;32m---> 42[1;33m from numba.np.ufunc import (vectorize, guvectorize, threading_layer,
[0m[0;32m     43[0m                             get_num_threads, set_num_threads)

[1;32m~\anaconda3\lib\site-packages\numba\np\ufunc\__init__.py[0m in [0;36m<module>[1;34m[0m
[0;32m      2[0m [1;33m[0m[0m
[1;32m----> 3[1;33m [1;32mfrom[0m [0mnumba[0m[1;33m.[0m[0mnp[0m[1;33m.[0m[0mufunc[0m[1;33m.[0m[0mdecorators[0m [1;32mimport[0m [0mVectorize[0m[1;33m,[0m [0mGUVectorize[0m[1;33m,[0m [0mvectorize[0m[1;33m,[0m [0mguvectorize[0m[1;33m[0m[1;33m[0m[0m
[0m[0;32m      4[0m [1;32mfrom[0m [0mnumba[0m[1;33m.[0m[0mnp[0m[1;33m.[0m[0mufunc[0m[1;33m.[0m[0m_internal[0m [1;32mimport[0m [0mPyUFunc_None[0m[1;33m,[0m [0mPyUFunc_Zero[0m[1;33m,[0m [0mPyUFunc_One[0m[1;33m[0m[1;33m[0m[0m

[1;32m~\anaconda3\lib\site-packages\numba\np\ufunc\decorators.py[0m in [0;36m<module>[1;34m[0m
[0;32m      2[0m [1;33m[0m[0m
[1;32m----> 3[1;33m [1;32mfrom[0m [0mnumba[0m[1;33m.[0m[0mnp[0m[1;33m.[0m[0mufunc[0m [1;32mimport[0m [0m_internal[0m[1;33m[0m[1;33m[0m[0m
[0m[0;32m      4[0m [1;32mfrom[0m [0mnumba[0m[1;33m.[0m[0mnp[0m[1;33m.[0m[0mufunc[0m[1;33m.[0m[0mparallel[0m [1;32mimport[0m [0mParallelUFuncBuilder[0m[1;33m,[0m [0mParallelGUFuncBuilder[0m[1;33m[0m[1;33m[0m[0m

[1;31mSystemError[0m: initialization of _internal failed without raising an exception

During handling of the above exception, another exception occurred:

[1;31mImportError[0m                               Traceback (most recent call last)
[1;32m~\AppData\Local\Temp\ipykernel_37452\21959343.py[0m in [0;36m<module>[1;34m[0m
[0;32m      3[0m [0mplt[0m[1;33m.[0m[0mrcParams[0m[1;33m[[0m[1;34m"figure.figsize"[0m[1;33m][0m [1;33m=[0m [1;33m([0m[1;36m11[0m[1;33m,[0m [1;36m5[0m[1;33m)[0m  [1;31m#set default figure size[0m[1;33m[0m[1;33m[0m[0m
[0;32m      4[0m [1;32mimport[0m [0mnumpy[0m [1;32mas[0m [0mnp[0m[1;33m[0m[1;33m[0m[0m
[1;32m----> 5[1;33m [1;32mimport[0m [0mquantecon[0m [1;32mas[0m [0mqe[0m[1;33m[0m[1;33m[0m[0m
[0m[0;32m      6[0m [1;32mfrom[0m [0minterpolation[0m [1;32mimport[0m [0minterp[0m[1;33m[0m[1;33m[0m[0m
[0;32m      7[0m [1;32mfrom[0m [0mnumpy[0m[1;33m.[0m[0mrandom[0m [1;32mimport[0m [0mrandn[0m[1;33m[0m[1;33m[0m[0m

[1;32m~\anaconda3\lib\site-packages\quantecon\__init__.py[0m in [0;36m<module>[1;34m[0m
[0;32m      9[0m     [1;32mimport[0m [0mnumba[0m[1;33m[0m[1;33m[0m[0m
[0;32m     10[0m [1;32mexcept[0m[1;33m:[0m[1;33m[0m[1;33m[0m[0m
[1;32m---> 11[1;33m     raise ImportError(
[0m[0;32m     12[0m         [0;31m"[0m[0mCannot[0m [1;32mimport[0m [0mnumba[0m [1;32mfrom[0m [0mcurrent[0m [0manaconda[0m [0mdistribution[0m[1;33m.[0m[0;31m [0m[0;31m\[0m[1;33m[0m[1;33m[0m[0m
[0;32m     13[0m             Please run `conda install numba` to install the latest version.")

[1;31mImportError[0m: Cannot import numba from current anaconda distribution.             Please run `conda install numba` to install the latest version.
ImportError: Cannot import numba from current anaconda distribution.             Please run `conda install numba` to install the latest version.

